Workbook

Sheet Actividades por fase
A1: Cronograma de Actividades – Ciclo de vida en cascada
A2: WBS | B2: Área de proceso | C2: Fase / Actividad | D2: Tipo | E2: Fase | F2: Fecha Inicio Planeada | G2: Fecha Final Planeada | H2: Horas Planeadas | I2: Fecha Inicio Real | J2: Fecha Final Real | K2: Horas Reales | L2: Responsable | M2: Avance (%)
A3: 1 | B3: Inicio | C3: Inicio | D3: Fase | E3: Inicio | F3: 46300 | G3: 46302 | H3: =SUM(H4:H10) -> 12.5 | K3: =SUM(K4:K10) -> 8 | M3: =IF(COUNTIFS($D$3:$D$10,"<>Fase")=0,"",ROUND(COUNTIFS($D$3:$D$10,"<>Fase",$J$3:$J$10,"<>")/COUNTIFS($D$3:$D$10,"<>Fase")*100,0)) -> 100
A4: 1.1 | B4: REQM – Gestión de Requisitos | C4: Entrevista de levantamiento de requisitos al cliente | D4: Actividad | E4: Inicio | F4: 46300 | G4: 46300 | H4: 2 | I4: 46300 | J4: 46300 | K4: 0.5 | L4: Luis Villegas (Analista) | M4: =IF($J4<>"",100,0) -> 100
A5: 1.2 | B5: PP – Planificación del Proyecto | C5: Reunión de arranque del proyecto | D5: Actividad | E5: Inicio | F5: 46300 | G5: 46300 | H5: 1.5 | I5: 46300 | J5: 46300 | K5: 0.5 | L5: Marco Muñoz (PM) | M5: =IF($J5<>"",100,0) -> 100
A6: 1.3 | B6: PP – Planificación del Proyecto | C6: Identificar objetivos generales del proyecto | D6: Actividad | E6: Inicio | F6: 46301 | G6: 46301 | H6: 2 | I6: 46301 | J6: 46302 | K6: 1 | L6: Marco Muñoz (PM) | M6: =IF($J6<>"",100,0) -> 100
A7: 1.4 | B7: PP – Planificación del Proyecto | C7: Identificar interesados principales | D7: Actividad | E7: Inicio | F7: 46301 | G7: 46301 | H7: 1.5 | I7: 46301 | J7: 46302 | K7: 1 | L7: Marco Muñoz (PM) | M7: =IF($J7<>"",100,0) -> 100
A8: 1.5 | B8: PP – Planificación del Proyecto | C8: Definir el alcance del proyecto | D8: Actividad | E8: Inicio | F8: 46302 | G8: 46302 | H8: 2.5 | I8: 46302 | J8: 46302 | K8: 2.5 | L8: Marco Muñoz (PM) | M8: =IF($J8<>"",100,0) -> 100
A9: 1.6 | B9: MA / PPQA – Medición y Calidad | C9: Elaborar métricas de la fase | D9: Actividad | E9: Inicio | F9: 46302 | G9: 46302 | H9: 1.5 | I9: 46302 | J9: 46302 | K9: 1.5 | L9: Marco Muñoz (PM) y Oliver (QA) | M9: 100
A10: 1.7 | B10: QA – Revisión documental | C10: Revisión de los documentos de la fase | D10: Revisión | E10: Inicio | F10: 46302 | G10: 46302 | H10: 1.5 | I10: 46302 | J10: 46302 | K10: 1 | L10: Oliver (QA) | M10: 100
A11: 2 | B11: Planificación | C11: Planificación | D11: Fase | E11: Planificación | F11: 46303 | G11: 46304 | H11: =SUM(H12:H18) -> 15.5 | K11: =SUM(K12:K18) -> 9 | M11: =IF(COUNTIFS($D$11:$D$18,"<>Fase")=0,"",ROUND(COUNTIFS($D$11:$D$18,"<>Fase",$J$11:$J$18,"<>")/COUNTIFS($D$11:$D$18,"<>Fase")*100,0)) -> 100
A12: 2.1 | B12: PP – Planificación del Proyecto | C12: Desarrollar el plan de proyecto | D12: Actividad | E12: Planificación | F12: 46303 | G12: 46303 | H12: 3 | I12: 46303 | J12: 46304 | K12: 2 | L12: Marco Muñoz (PM) | M12: =IF($J12<>"",100,0) -> 100
A13: 2.2 | B13: PP – Planificación del Proyecto | C13: Elaborar la estructura de trabajo (WBS) | D13: Actividad | E13: Planificación | F13: 46303 | G13: 46303 | H13: 2.5 | I13: 46303 | J13: 46304 | K13: 1.5 | L13: Marco Muñoz (PM) | M13: =IF($J13<>"",100,0) -> 100
A14: 2.3 | B14: PP – Planificación del Proyecto | C14: Desarrollar el cronograma de actividades | D14: Actividad | E14: Planificación | F14: 46300 | G14: 46304 | H14: 2.5 | I14: 46302 | J14: 46304 | K14: 2 | L14: Marco Muñoz (PM) | M14: =IF($J14<>"",100,0) -> 100
A15: 2.4 | B15: PP – Planificación del Proyecto | C15: Identificar y documentar riesgos | D15: Actividad | E15: Planificación | F15: 46304 | G15: 46304 | H15: 2.5 | I15: 46304 | J15: 46304 | K15: 1 | L15: Marco Muñoz (PM) y Oliver (QA) | M15: =IF($J15<>"",100,0) -> 100
A16: 2.5 | B16: PP – Planificación del Proyecto | C16: Planificar recursos, comunicaciones y calidad | D16: Actividad | E16: Planificación | F16: 46304 | G16: 46304 | H16: 2 | I16: 46304 | J16: 46304 | K16: 1 | L16: Marco Muñoz (PM) | M16: =IF($J16<>"",100,0) -> 100
A17: 2.6 | B17: MA / PPQA – Medición y Calidad | C17: Elaborar métricas de la fase | D17: Actividad | E17: Planificación | F17: 46304 | G17: 46304 | H17: 1.5 | I17: 46304 | J17: 46304 | K17: 0.8 | L17: Marco Muñoz (PM) y Oliver (QA) | M17: =IF($J17<>"",100,0) -> 100
A18: 2.7 | B18: QA – Revisión documental | C18: Revisión de los documentos de la fase | D18: Revisión | E18: Planificación | F18: 46304 | G18: 46304 | H18: 1.5 | I18: 46304 | J18: 46304 | K18: 0.7 | L18: Oliver (QA) | M18: =IF($J18<>"",100,0) -> 100
A19: 3 | B19: Análisis | C19: Análisis | D19: Fase | E19: Análisis | F19: 46307 | G19: 46310 | H19: =SUM(H20:H27) -> 25 | K19: =SUM(K20:K27) -> 18.5 | M19: =IF(COUNTIFS($D$19:$D$27,"<>Fase")=0,"",ROUND(COUNTIFS($D$19:$D$27,"<>Fase",$J$19:$J$27,"<>")/COUNTIFS($D$19:$D$27,"<>Fase")*100,0)) -> 100
A20: 3.1 | B20: REQM – Gestión de Requisitos | C20: Recopilar y documentar los requisitos (SRS) | D20: Actividad | E20: Análisis | F20: 46307 | G20: 46308 | H20: 6 | I20: 46307 | J20: 46307 | K20: 5 | L20: Luis Villegas (Analista) | M20: =IF($J20<>"",100,0) -> 100
A21: 3.2 | B21: PP – Planificación del Proyecto | C21: Elaborar la complejidad del software | D21: Actividad | E21: Análisis | F21: 46309 | G21: 46309 | H21: 2 | I21: 46307 | J21: 46307 | K21: 1.5 | L21: Marco Muñoz (PM) | M21: =IF($J21<>"",100,0) -> 100
A22: 3.3 | B22: REQM – Gestión de Requisitos | C22: Elaborar los casos de uso | D22: Actividad | E22: Análisis | F22: 46308 | G22: 46308 | H22: 4 | I22: 46307 | J22: 46307 | K22: 3 | L22: Luis Villegas (Analista) | M22: =IF($J22<>"",100,0) -> 100
A23: 3.4 | B23: REQM – Gestión de Requisitos | C23: Elaborar el prototipo de interfaz | D23: Actividad | E23: Análisis | F23: 46309 | G23: 46309 | H23: 4 | I23: 46309 | J23: 46309 | K23: 3 | L23: Luis Villegas y Javier | M23: =IF($J23<>"",100,0) -> 100
A24: 3.5 | B24: REQM / PPQA – Requisitos y Calidad | C24: Validar y refinar los requisitos | D24: Actividad | E24: Análisis | F24: 46309 | G24: 46310 | H24: 3 | I24: 46309 | J24: 46309 | K24: 2 | L24: Equipo y profesor (cliente) | M24: =IF($J24<>"",100,0) -> 100
A25: 3.6 | B25: REQM / CM – Requisitos y Configuración | C25: Establecer la línea base de requisitos | D25: Actividad | E25: Análisis | F25: 46310 | G25: 46310 | H25: 2 | I25: 46309 | J25: 46128 | K25: 1.5 | L25: Marco Muñoz (PM) | M25: =IF($J25<>"",100,0) -> 100
A26: 3.7 | B26: MA / PPQA – Medición y Calidad | C26: Elaborar métricas de la fase | D26: Actividad | E26: Análisis | F26: 46310 | G26: 46310 | H26: 2 | I26: 46309 | J26: 46128 | K26: 1.5 | L26: Marco Muñoz (PM) y Oliver (QA) | M26: =IF($J26<>"",100,0) -> 100
A27: 3.8 | B27: QA – Revisión documental | C27: Revisión de los documentos de la fase | D27: Revisión | E27: Análisis | F27: 46310 | G27: 46310 | H27: 2 | I27: 46309 | J27: 46128 | K27: 1 | L27: Oliver (QA) | M27: =IF($J27<>"",100,0) -> 100
A28: 4 | B28: Diseño | C28: Diseño | D28: Fase | E28: Diseño | F28: 46311 | G28: 46315 | H28: =SUM(H29:H35) -> 20.5 | K28: =SUM(K29:K35) -> 0 | M28: =IF(COUNTIFS($D$28:$D$35,"<>Fase")=0,"",ROUND(COUNTIFS($D$28:$D$35,"<>Fase",$J$28:$J$35,"<>")/COUNTIFS($D$28:$D$35,"<>Fase")*100,0)) -> 0
A29: 4.1 | B29: CM – Gestión de Configuración | C29: Definir la arquitectura general del sistema | D29: Actividad | E29: Diseño | F29: 46311 | G29: 46311 | H29: 4 | L29: Javier (Arquitecto) | M29: =IF($J29<>"",100,0) -> 0
A30: 4.2 | B30: CM – Gestión de Configuración | C30: Diseñar componentes y módulos | D30: Actividad | E30: Diseño | F30: 46314 | G30: 46314 | H30: 4 | L30: Javier y José | M30: =IF($J30<>"",100,0) -> 0
A31: 4.3 | B31: CM – Gestión de Configuración | C31: Diseñar las estructuras de información (base de datos) | D31: Actividad | E31: Diseño | F31: 46314 | G31: 46314 | H31: 4 | L31: José | M31: =IF($J31<>"",100,0) -> 0
A32: 4.4 | B32: PPQA – Aseguramiento de Calidad | C32: Diseñar las interfaces de usuario | D32: Actividad | E32: Diseño | F32: 46315 | G32: 46315 | H32: 3.5 | L32: Javier (Arquitecto) | M32: =IF($J32<>"",100,0) -> 0
A33: 4.5 | B33: PP – Planificación del Proyecto | C33: Definir el plan de integración de componentes | D33: Actividad | E33: Diseño | F33: 46315 | G33: 46315 | H33: 2 | L33: Javier (Arquitecto) | M33: =IF($J33<>"",100,0) -> 0
A34: 4.6 | B34: MA / PPQA – Medición y Calidad | C34: Elaborar métricas de la fase | D34: Actividad | E34: Diseño | F34: 46315 | G34: 46315 | H34: 1.5 | L34: Marco Muñoz (PM) y Oliver (QA) | M34: =IF($J34<>"",100,0) -> 0
A35: 4.7 | B35: QA – Revisión documental | C35: Revisión de los documentos de la fase | D35: Revisión | E35: Diseño | F35: 46315 | G35: 46315 | H35: 1.5 | L35: Oliver (QA) | M35: =IF($J35<>"",100,0) -> 0
A36: 5 | B36: Codificación | C36: Codificación | D36: Fase | E36: Codificación | F36: 46316 | G36: 46321 | H36: =SUM(H37:H43) -> 38 | K36: =SUM(K37:K43) -> 0 | M36: =IF(COUNTIFS($D$36:$D$43,"<>Fase")=0,"",ROUND(COUNTIFS($D$36:$D$43,"<>Fase",$J$36:$J$43,"<>")/COUNTIFS($D$36:$D$43,"<>Fase")*100,0)) -> 0
A37: 5.1 | B37: CM – Gestión de Configuración | C37: Preparar el entorno de desarrollo | D37: Actividad | E37: Codificación | F37: 46316 | G37: 46316 | H37: 3 | L37: Javier (Arquitecto) | M37: =IF($J37<>"",100,0) -> 0
A38: 5.2 | B38: CM – Gestión de Configuración | C38: Programar la autenticación y la matriz de permisos | D38: Actividad | E38: Codificación | F38: 46316 | G38: 46317 | H38: 7 | L38: Javier y José | M38: =IF($J38<>"",100,0) -> 0
A39: 5.3 | B39: CM – Gestión de Configuración | C39: Programar el registro de usuarios y de equipos | D39: Actividad | E39: Codificación | F39: 46317 | G39: 46318 | H39: 7 | L39: José | M39: =IF($J39<>"",100,0) -> 0
A40: 5.4 | B40: CM – Gestión de Configuración | C40: Programar el préstamo, la devolución y el bloqueo por vencido | D40: Actividad | E40: Codificación | F40: 46318 | G40: 46321 | H40: 9 | L40: Javier y José | M40: =IF($J40<>"",100,0) -> 0
...

Sheet Resumen por fase
A1: Resumen de Avance y Esfuerzo por Fase (MA)
A2: Fase | B2: Inicio planeado | C2: Fin planeado | D2: Días hábiles | E2: Actividades | F2: Horas planeadas | G2: Horas reales | H2: % Avance
A3: 1. Inicio | B3: 46300 | C3: 46302 | D3: 3 | E3: =COUNTIFS('Actividades por fase'!$E$3:$E$59,"Inicio",'Actividades por fase'!$D$3:$D$59,"<>Fase") -> 7 | F3: 12.5 | G3: =SUMIF('Actividades por fase'!$E$3:$E$59,"Inicio",'Actividades por fase'!$K$3:$K$59) -> 16 | H3: =IF($E3=0,"",ROUND(COUNTIFS('Actividades por fase'!$E$3:$E$59,"Inicio",'Actividades por fase'!$D$3:$D$59,"<>Fase",'Actividades por fase'!$J$3:$J$59,"<>")/$E3*100,0)) -> 100
A4: 2. Planificación | B4: 46303 | C4: 46304 | D4: 2 | E4: =COUNTIFS('Actividades por fase'!$E$3:$E$59,"Planificación",'Actividades por fase'!$D$3:$D$59,"<>Fase") -> 7 | F4: 15.5 | G4: =SUMIF('Actividades por fase'!$E$3:$E$59,"Planificación",'Actividades por fase'!$K$3:$K$59) -> 18 | H4: =IF($E4=0,"",ROUND(COUNTIFS('Actividades por fase'!$E$3:$E$59,"Planificación",'Actividades por fase'!$D$3:$D$59,"<>Fase",'Actividades por fase'!$J$3:$J$59,"<>")/$E4*100,0)) -> 100
A5: 3. Análisis | B5: 46307 | C5: 46310 | D5: 4 | E5: =COUNTIFS('Actividades por fase'!$E$3:$E$59,"Análisis",'Actividades por fase'!$D$3:$D$59,"<>Fase") -> 8 | F5: 25 | G5: =SUMIF('Actividades por fase'!$E$3:$E$59,"Análisis",'Actividades por fase'!$K$3:$K$59) -> 37 | H5: =IF($E5=0,"",ROUND(COUNTIFS('Actividades por fase'!$E$3:$E$59,"Análisis",'Actividades por fase'!$D$3:$D$59,"<>Fase",'Actividades por fase'!$J$3:$J$59,"<>")/$E5*100,0)) -> 100
A6: 4. Diseño | B6: 46311 | C6: 46315 | D6: 3 | E6: =COUNTIFS('Actividades por fase'!$E$3:$E$59,"Diseño",'Actividades por fase'!$D$3:$D$59,"<>Fase") -> 7 | F6: 20.5 | G6: =SUMIF('Actividades por fase'!$E$3:$E$59,"Diseño",'Actividades por fase'!$K$3:$K$59) -> 0 | H6: =IF($E6=0,"",ROUND(COUNTIFS('Actividades por fase'!$E$3:$E$59,"Diseño",'Actividades por fase'!$D$3:$D$59,"<>Fase",'Actividades por fase'!$J$3:$J$59,"<>")/$E6*100,0)) -> 0
A7: 5. Codificación | B7: 46316 | C7: 46321 | D7: 4 | E7: =COUNTIFS('Actividades por fase'!$E$3:$E$59,"Codificación",'Actividades por fase'!$D$3:$D$59,"<>Fase") -> 7 | F7: 38 | G7: =SUMIF('Actividades por fase'!$E$3:$E$59,"Codificación",'Actividades por fase'!$K$3:$K$59) -> 0 | H7: =IF($E7=0,"",ROUND(COUNTIFS('Actividades por fase'!$E$3:$E$59,"Codificación",'Actividades por fase'!$D$3:$D$59,"<>Fase",'Actividades por fase'!$J$3:$J$59,"<>")/$E7*100,0)) -> 0
A8: 6. Pruebas QA | B8: 46322 | C8: 46323 | D8: 2 | E8: =COUNTIFS('Actividades por fase'!$E$3:$E$59,"Pruebas QA",'Actividades por fase'!$D$3:$D$59,"<>Fase") -> 7 | F8: 18.5 | G8: =SUMIF('Actividades por fase'!$E$3:$E$59,"Pruebas QA",'Actividades por fase'!$K$3:$K$59) -> 0 | H8: =IF($E8=0,"",ROUND(COUNTIFS('Actividades por fase'!$E$3:$E$59,"Pruebas QA",'Actividades por fase'!$D$3:$D$59,"<>Fase",'Actividades por fase'!$J$3:$J$59,"<>")/$E8*100,0)) -> 0
A9: 7. Implementación | B9: 46324 | C9: 46325 | D9: 2 | E9: =COUNTIFS('Actividades por fase'!$E$3:$E$59,"Implementación",'Actividades por fase'!$D$3:$D$59,"<>Fase") -> 7 | F9: 16 | G9: =SUMIF('Actividades por fase'!$E$3:$E$59,"Implementación",'Actividades por fase'!$K$3:$K$59) -> 0 | H9: =IF($E9=0,"",ROUND(COUNTIFS('Actividades por fase'!$E$3:$E$59,"Implementación",'Actividades por fase'!$D$3:$D$59,"<>Fase",'Actividades por fase'!$J$3:$J$59,"<>")/$E9*100,0)) -> 0
A10: TOTAL | D10: =SUM(D3:D9) -> 20 | E10: =SUM(E3:E9) -> 50 | F10: =SUM(F3:F9) -> 146 | G10: =SUM(G3:G9) -> 71 | H10: =IF(COUNTIFS('Actividades por fase'!$D$3:$D59,"<>Fase")=0,"",ROUND(COUNTIFS('Actividades por fase'!$D$3:$D59,"<>Fase",'Actividades por fase'!$J$3:$J59,"<>")/COUNTIFS('Actividades por fase'!$D$3:$D59,"<>Fase")*100,0)) -> 44
A12: Métricas del proyecto
A13: • Esfuerzo total planeado: 146.0 horas repartidas en 20 días hábiles (del 05/10/2026 al 30/10/2026).
A14: • % Avance = (Actividades con Fecha Final Real registrada ÷ Total de paquetes de la fase) × 100.
A15: • Desviación en días, índice de eficiencia (HP/HR) y estado se calculan en el documento de métricas al cierre de cada fase (1.6, 2.6, 3.7, 4.6, 5.6, 6.6 y 7.6).
A16: • Todas las cifras de horas reales se capturan al cierre de cada actividad; hoy la columna queda vacía.

Sheet Control de Firmas
A1: Control de Firmas por Documento
A2: Documento | B2: WBS | C2: Fase | D2: Fecha | E2: Firma requerida
A3: Entrevista de Levantamiento de Requisitos | B3: 1.1 | C3: Inicio | D3: 05/10/2026 | E3: Profesor (Cliente) + Luis Villegas + Marco Muñoz (PM)
A4: Minuta de Reunión de Arranque | B4: 1.2 | C4: Inicio | D4: 05/10/2026 | E4: Todo el equipo (6 integrantes)
A5: Objetivos del Proyecto | B5: 1.3 | C5: Inicio | D5: 06/10/2026 | E5: Marco Muñoz (PM)
A6: Identificación de Interesados | B6: 1.4 | C6: Inicio | D6: 06/10/2026 | E6: Marco Muñoz (PM)
A7: Alcance del Proyecto | B7: 1.5 | C7: Inicio | D7: 07/10/2026 | E7: Profesor (Cliente) + Marco Muñoz (PM)
A8: Métricas de la Fase Inicio (MA) | B8: 1.6 | C8: Inicio | D8: 07/10/2026 | E8: José Oliver Guzmán Camacho (QA) + Marco Muñoz (PM)
A9: Checklist de Revisión QA – Inicio | B9: 1.7 | C9: Inicio | D9: 07/10/2026 | E9: Oliver (QA) + Marco Muñoz (PM)
A10: Plan de Proyecto | B10: 2.1 | C10: Planificación | D10: 08/10/2026 | E10: Marco Muñoz (PM)
A11: Estructura de Trabajo (WBS) | B11: 2.2 | C11: Planificación | D11: 08/10/2026 | E11: Marco Muñoz (PM)
A12: Cronograma del Proyecto (Excel) | B12: 2.3 | C12: Planificación | D12: 09/10/2026 | E12: Marco Muñoz (PM)
A13: Registro de Riesgos | B13: 2.4 | C13: Planificación | D13: 09/10/2026 | E13: Marco Muñoz (PM) + Oliver (QA)
... A52: Auditoría Final CMMI | B52: 7.7 | C52: Implementación | D52: 30/10/2026 | E52: Oliver (QA)
A54: Total de documentos que requieren firma: 50
A56: Convenciones del cronograma
A57: • Fecha planeada: fecha en la que el equipo se comprometió a entregar el documento o a ejecutar la actividad.
A58: • Fecha real: fecha en la que realmente se terminó. Se registra al cerrar la actividad.
A59: • Horas planeadas: esfuerzo estimado en horas persona, asignado en la planificación (2.3).
A60: • Horas reales: esfuerzo efectivamente dedicado. Se registra al cierre y alimenta las métricas de la fase (documentos *6 de cada fase).
A61: • Revisión QA: actividad que Oliver (QA) ejecuta al cierre de cada fase para verificar que todos los documentos de la fase existan y sean coherentes con el cronograma.
